<?xml version="1.0" encoding="utf-8"?>
<mujoco>
    
    <compiler angle="radian" coordinate="local" meshdir="../stls/hand" texturedir="../textures"></compiler>
    <option timestep="0.00555" iterations="20" apirate="200">
        <flag warmstart="enable"></flag>
    </option>

    <size njmax="500" nconmax="100" nuser_jnt="1" nuser_site="1" nuser_tendon="1" nuser_sensor="1" nuser_actuator="16" nstack="600000"></size>

    <visual>
        <map fogstart="3" fogend="5" force="0.1"></map>
        <quality shadowsize="4096"></quality>
    </visual>

    <default>
        <default class="robot0:asset_class">
            <geom friction="1 0.005 0.001" condim="3" margin="0.0005" contype="1" conaffinity="1"></geom>
            <joint limited="true" damping="0.1" armature="0.001" margin="0.01" frictionloss="0.001"></joint>
            <site size="0.005" rgba="0.4 0.9 0.4 1"></site>
            <general ctrllimited="true" forcelimited="true"></general>
        </default>
        <default class="robot0:D_Touch">
            <site type="box" size="0.009 0.004 0.013" pos="0 -0.004 0.018" rgba="0.8 0.8 0.8 0.15" group="4"></site>
        </default>
        <default class="robot0:DC_Hand">
            <geom material="robot0:MatColl" contype="1" conaffinity="0" group="4"></geom>
        </default>
        <default class="robot0:D_Vizual">
            <geom material="robot0:MatViz" contype="0" conaffinity="0" group="1" type="mesh"></geom>
        </default>
        <default class="robot0:free">
            <joint type="free" damping="0" armature="0" limited="false"></joint>
        </default>

        <motor ctrlrange="-1 1" ctrllimited="true"/>
        <default class="body">
          <geom type="capsule" condim="1" friction="1.0 0.05 0.05" solimp=".9 .99 .003" solref=".015 1"/>
          <joint type="hinge" damping="0.1" stiffness="5" armature=".007" limited="true" solimplimit="0 .99 .01"/>
          <site size=".04" group="3"/>
          <default class="force-torque">
            <site type="box" size=".01 .01 .02" rgba="1 0 0 1" />
          </default>
          <default class="touch">
            <site type="capsule" rgba="0 0 1 .3"/>
          </default>
        </default>

    </default>

    <contact>
        <pair geom1="robot0:C_ffdistal" geom2="robot0:C_thdistal" condim="1"></pair>
        <pair geom1="robot0:C_ffmiddle" geom2="robot0:C_thdistal" condim="1"></pair>
        <pair geom1="robot0:C_ffproximal" geom2="robot0:C_thdistal" condim="1"></pair>
        <pair geom1="robot0:C_mfproximal" geom2="robot0:C_thdistal" condim="1"></pair>
        <pair geom1="robot0:C_mfdistal" geom2="robot0:C_thdistal" condim="1"></pair>
        <pair geom1="robot0:C_rfdistal" geom2="robot0:C_thdistal" condim="1"></pair>
        <pair geom1="robot0:C_lfdistal" geom2="robot0:C_thdistal" condim="1"></pair>
        <pair geom1="robot0:C_palm0" geom2="robot0:C_thdistal" condim="1"></pair>
        <pair geom1="robot0:C_mfdistal" geom2="robot0:C_ffdistal" condim="1"></pair>
        <pair geom1="robot0:C_rfdistal" geom2="robot0:C_mfdistal" condim="1"></pair>
        <pair geom1="robot0:C_lfdistal" geom2="robot0:C_rfdistal" condim="1"></pair>
        <pair geom1="robot0:C_mfproximal" geom2="robot0:C_ffproximal" condim="1"></pair>
        <pair geom1="robot0:C_rfproximal" geom2="robot0:C_mfproximal" condim="1"></pair>
        <pair geom1="robot0:C_lfproximal" geom2="robot0:C_rfproximal" condim="1"></pair>
        <pair geom1="robot0:C_lfdistal" geom2="robot0:C_rfdistal" condim="1"></pair>
        <pair geom1="robot0:C_lfdistal" geom2="robot0:C_mfdistal" condim="1"></pair>
        <pair geom1="robot0:C_lfdistal" geom2="robot0:C_rfmiddle" condim="1"></pair>
        <pair geom1="robot0:C_lfmiddle" geom2="robot0:C_rfdistal" condim="1"></pair>
        <pair geom1="robot0:C_lfmiddle" geom2="robot0:C_rfmiddle" condim="1"></pair>
    </contact>

    <tendon>
        <fixed name="robot0:T_FFJ1c" limited="true" range="-0.001 0.001">
            <joint joint="robot0:FFJ0" coef="0.00705"></joint>
            <joint joint="robot0:FFJ1" coef="-0.00805"></joint>
        </fixed>
        <fixed name="robot0:T_MFJ1c" limited="true" range="-0.001 0.001">
            <joint joint="robot0:MFJ0" coef="0.00705"></joint>
            <joint joint="robot0:MFJ1" coef="-0.00805"></joint>
        </fixed>
        <fixed name="robot0:T_RFJ1c" limited="true" range="-0.001 0.001">
            <joint joint="robot0:RFJ0" coef="0.00705"></joint>
            <joint joint="robot0:RFJ1" coef="-0.00805"></joint>
        </fixed>
        <fixed name="robot0:T_LFJ1c" limited="true" range="-0.001 0.001">
            <joint joint="robot0:LFJ0" coef="0.00705"></joint>
            <joint joint="robot0:LFJ1" coef="-0.00805"></joint>
        </fixed>
    </tendon>

    <sensor>
        <jointpos name="robot0:Sjp_FFJ3" joint="robot0:FFJ3"></jointpos>
        <jointpos name="robot0:Sjp_FFJ2" joint="robot0:FFJ2"></jointpos>
        <jointpos name="robot0:Sjp_FFJ1" joint="robot0:FFJ1"></jointpos>
        <jointpos name="robot0:Sjp_FFJ0" joint="robot0:FFJ0"></jointpos>
        <jointpos name="robot0:Sjp_MFJ3" joint="robot0:MFJ3"></jointpos>
        <jointpos name="robot0:Sjp_MFJ2" joint="robot0:MFJ2"></jointpos>
        <jointpos name="robot0:Sjp_MFJ1" joint="robot0:MFJ1"></jointpos>
        <jointpos name="robot0:Sjp_MFJ0" joint="robot0:MFJ0"></jointpos>
        <jointpos name="robot0:Sjp_RFJ3" joint="robot0:RFJ3"></jointpos>
        <jointpos name="robot0:Sjp_RFJ2" joint="robot0:RFJ2"></jointpos>
        <jointpos name="robot0:Sjp_RFJ1" joint="robot0:RFJ1"></jointpos>
        <jointpos name="robot0:Sjp_RFJ0" joint="robot0:RFJ0"></jointpos>
        <jointpos name="robot0:Sjp_LFJ4" joint="robot0:LFJ4"></jointpos>
        <jointpos name="robot0:Sjp_LFJ3" joint="robot0:LFJ3"></jointpos>
        <jointpos name="robot0:Sjp_LFJ2" joint="robot0:LFJ2"></jointpos>
        <jointpos name="robot0:Sjp_LFJ1" joint="robot0:LFJ1"></jointpos>
        <jointpos name="robot0:Sjp_LFJ0" joint="robot0:LFJ0"></jointpos>
        <jointpos name="robot0:Sjp_THJ4" joint="robot0:THJ4"></jointpos>
        <jointpos name="robot0:Sjp_THJ3" joint="robot0:THJ3"></jointpos>
        <jointpos name="robot0:Sjp_THJ2" joint="robot0:THJ2"></jointpos>
        <jointpos name="robot0:Sjp_THJ1" joint="robot0:THJ1"></jointpos>
        <jointpos name="robot0:Sjp_THJ0" joint="robot0:THJ0"></jointpos>
        <touch name="robot0:ST_Tch_fftip" site="robot0:Tch_fftip"></touch>
        <touch name="robot0:ST_Tch_mftip" site="robot0:Tch_mftip"></touch>
        <touch name="robot0:ST_Tch_rftip" site="robot0:Tch_rftip"></touch>
        <touch name="robot0:ST_Tch_lftip" site="robot0:Tch_lftip"></touch>
        <touch name="robot0:ST_Tch_thtip" site="robot0:Tch_thtip"></touch>


        <subtreelinvel name="pelvis_subtreelinvel" body="pelvis"/>
        <accelerometer name="root_accel"    site="root"/>
        <velocimeter name="root_vel"        site="root"/>
        <gyro name="root_gyro"              site="root"/>

        <force name="left_ankle_force"       site="left_ankle"/>
        <force name="right_ankle_force"      site="right_ankle"/>
        <force name="left_knee_force"        site="left_knee"/>
        <force name="right_knee_force"       site="right_knee"/>
        <force name="left_hip_force"         site="left_hip"/>
        <force name="right_hip_force"        site="right_hip"/>

        <torque name="left_ankle_torque"     site="left_ankle"/>
        <torque name="right_ankle_torque"    site="right_ankle"/>
        <torque name="left_knee_torque"      site="left_knee"/>
        <torque name="right_knee_torque"     site="right_knee"/>
        <torque name="left_hip_torque"       site="left_hip"/>
        <torque name="right_hip_torque"      site="right_hip"/>

        <touch name="pelvis_touch"           site="pelvis"/>
        <touch name="upper_waist_touch"      site="upper_waist"/>
        <touch name="torso_touch"            site="torso"/>
        <touch name="head_touch"             site="head"/>
        <touch name="right_upper_arm_touch"  site="right_upper_arm"/>
        <touch name="right_lower_arm_touch"  site="right_lower_arm"/>
        <!-- <touch name="right_hand_touch"       site="right_hand"/> -->
        <touch name="left_upper_arm_touch"   site="left_upper_arm"/>
        <touch name="left_lower_arm_touch"   site="left_lower_arm"/>
        <touch name="left_hand_touch"        site="left_hand"/>
        <touch name="right_thigh_touch"      site="right_thigh"/>
        <touch name="right_shin_touch"       site="right_shin"/>
        <touch name="right_foot_touch"       site="right_foot"/>
        <touch name="left_thigh_touch"       site="left_thigh"/>
        <touch name="left_shin_touch"        site="left_shin"/>
        <touch name="left_foot_touch"        site="left_foot"/>

        <jointpos name="robot0:Sjp_WRJ1" joint="robot0:WRJ1"></jointpos>
        <jointpos name="robot0:Sjp_WRJ0" joint="robot0:WRJ0"></jointpos>
    </sensor>

    <actuator>
        <position name="robot0:A_WRJ1" class="robot0:asset_class" user="2038" joint="robot0:WRJ1" ctrlrange="-0.489 0.14" kp="5" forcerange="-4.785 4.785"></position>
        <position name="robot0:A_WRJ0" class="robot0:asset_class" user="2036" joint="robot0:WRJ0" ctrlrange="-0.698 0.489" kp="5" forcerange="-2.175 2.175"></position>

        <position name="robot0:A_FFJ3" class="robot0:asset_class" user="2004" joint="robot0:FFJ3" ctrlrange="-0.349 0.349" kp="1" forcerange="-0.9 0.9"></position>
        <position name="robot0:A_FFJ2" class="robot0:asset_class" user="2002" joint="robot0:FFJ2" ctrlrange="0 1.571" kp="1" forcerange="-0.9 0.9"></position>
        <position name="robot0:A_FFJ1" class="robot0:asset_class" user="2000" joint="robot0:FFJ1" ctrlrange="0 1.571" kp="1" forcerange="-0.7245 0.7245"></position>
        <position name="robot0:A_MFJ3" class="robot0:asset_class" user="2010" joint="robot0:MFJ3" ctrlrange="-0.349 0.349" kp="1" forcerange="-0.9 0.9"></position>
        <position name="robot0:A_MFJ2" class="robot0:asset_class" user="2008" joint="robot0:MFJ2" ctrlrange="0 1.571" kp="1" forcerange="-0.9 0.9"></position>
        <position name="robot0:A_MFJ1" class="robot0:asset_class" user="2006" joint="robot0:MFJ1" ctrlrange="0 1.571" kp="1" forcerange="-0.7245 0.7245"></position>
        <position name="robot0:A_RFJ3" class="robot0:asset_class" user="2016" joint="robot0:RFJ3" ctrlrange="-0.349 0.349" kp="1" forcerange="-0.9 0.9"></position>
        <position name="robot0:A_RFJ2" class="robot0:asset_class" user="2014" joint="robot0:RFJ2" ctrlrange="0 1.571" kp="1" forcerange="-0.9 0.9"></position>
        <position name="robot0:A_RFJ1" class="robot0:asset_class" user="2012" joint="robot0:RFJ1" ctrlrange="0 1.571" kp="1" forcerange="-0.7245 0.7245"></position>
        <position name="robot0:A_LFJ4" class="robot0:asset_class" user="2024" joint="robot0:LFJ4" ctrlrange="0 0.785" kp="1" forcerange="-0.9 0.9"></position>
        <position name="robot0:A_LFJ3" class="robot0:asset_class" user="2022" joint="robot0:LFJ3" ctrlrange="-0.349 0.349" kp="1" forcerange="-0.9 0.9"></position>
        <position name="robot0:A_LFJ2" class="robot0:asset_class" user="2020" joint="robot0:LFJ2" ctrlrange="0 1.571" kp="1" forcerange="-0.9 0.9"></position>
        <position name="robot0:A_LFJ1" class="robot0:asset_class" user="2018" joint="robot0:LFJ1" ctrlrange="0 1.571" kp="1" forcerange="-0.7245 0.7245"></position>
        <position name="robot0:A_THJ4" class="robot0:asset_class" user="2034" joint="robot0:THJ4" ctrlrange="-1.047 1.047" kp="1" forcerange="-2.3722 2.3722"></position>
        <position name="robot0:A_THJ3" class="robot0:asset_class" user="2032" joint="robot0:THJ3" ctrlrange="0 1.222" kp="1" forcerange="-1.45 1.45"></position>
        <position name="robot0:A_THJ2" class="robot0:asset_class" user="2030" joint="robot0:THJ2" ctrlrange="-0.209 0.209" kp="1" forcerange="-0.99 0.99"></position>
        <position name="robot0:A_THJ1" class="robot0:asset_class" user="2028" joint="robot0:THJ1" ctrlrange="-0.524 0.524" kp="1" forcerange="-0.99 0.99"></position>
        <position name="robot0:A_THJ0" class="robot0:asset_class" user="2026" joint="robot0:THJ0" ctrlrange="-1.571 0" kp="1" forcerange="-0.81 0.81"></position>

        <motor name='abdomen_x'       gear='125' joint='abdomen_x'/>
        <motor name='abdomen_y'       gear='125' joint='abdomen_y'/>
        <motor name='abdomen_z'       gear='125' joint='abdomen_z'/>
        <motor name='neck_x'          gear='20' joint='neck_x'/>
        <motor name='neck_y'          gear='20' joint='neck_y'/>
        <motor name='neck_z'          gear='20' joint='neck_z'/>
        <motor name='right_shoulder_x' gear='70' joint='right_shoulder_x'/>
        <motor name='right_shoulder_y' gear='70' joint='right_shoulder_y'/>
        <motor name='right_shoulder_z' gear='70' joint='right_shoulder_z'/>
        <motor name='right_elbow'     gear='60' joint='right_elbow'/>
        <motor name='left_shoulder_x'  gear='70' joint='left_shoulder_x'/>
        <motor name='left_shoulder_y'  gear='70' joint='left_shoulder_y'/>
        <motor name='left_shoulder_z'  gear='70' joint='left_shoulder_z'/>
        <motor name='left_elbow'      gear='60' joint='left_elbow'/>
        <motor name='right_hip_x'     gear='125' joint='right_hip_x'/>
        <motor name='right_hip_z'     gear='125' joint='right_hip_z'/>
        <motor name='right_hip_y'     gear='125' joint='right_hip_y'/>
        <motor name='right_knee'      gear='100' joint='right_knee'/>
        <motor name='right_ankle_x'   gear='50' joint='right_ankle_x'/>
        <motor name='right_ankle_y'   gear='50' joint='right_ankle_y'/>
        <motor name='right_ankle_z'   gear='50' joint='right_ankle_z'/>
        <motor name='left_hip_x'      gear='125' joint='left_hip_x'/>
        <motor name='left_hip_z'      gear='125' joint='left_hip_z'/>
        <motor name='left_hip_y'      gear='125' joint='left_hip_y'/>
        <motor name='left_knee'       gear='100' joint='left_knee'/>
        <motor name='left_ankle_x'    gear='50' joint='left_ankle_x'/>
        <motor name='left_ankle_y'    gear='50' joint='left_ankle_y'/>
        <motor name='left_ankle_z'    gear='50' joint='left_ankle_z'/>
    </actuator>

    <asset>
        <texture type="skybox" builtin="gradient" rgb1="0.44 0.85 0.56" rgb2="0.46 0.87 0.58" width="32" height="32"></texture>
        <texture name="floor_tex" type="2d" file="../textures/texture_background_wall_paint_2.jpg"/>
        <!-- <material name="floor_mat" texture="floor_tex"/> -->
        <texture name="robot0:texplane" type="2d" builtin="checker" rgb1="0.2 0.3 0.4" rgb2="0.1 0.15 0.2" width="512" height="512"></texture>
        <texture name="robot0:texgeom" type="cube" builtin="flat" mark="cross" width="127" height="127" rgb1="0.3 0.6 0.5" rgb2="0.3 0.6 0.5" markrgb="0 0 0" random="0.01"></texture>

        <material name="robot0:MatGnd" reflectance="0.5" texture="robot0:texplane" texrepeat="1 1" texuniform="true"></material>
        <material name="robot0:MatColl" specular="1" shininess="0.3" reflectance="0.5" rgba="0.4 0.5 0.6 1"></material>
        <material name="robot0:MatViz" specular="0.75" shininess="0.1" reflectance="0.5" rgba="0.93 0.93 0.93 1"></material>
        <material name="robot0:object" texture="robot0:texgeom" texuniform="false"></material>
        <material name="floor_mat" specular="0" shininess="0.5" reflectance="0" rgba="0.2 0.2 0.2 0"></material>

        <mesh name="robot0:palm" scale="0.001 0.001 0.001" file="palm.stl"></mesh>
        <mesh name="robot0:knuckle" scale="0.001 0.001 0.001" file="knuckle.stl"></mesh>
        <mesh name="robot0:F3" scale="0.001 0.001 0.001" file="F3.stl"></mesh>
        <mesh name="robot0:F2" scale="0.001 0.001 0.001" file="F2.stl"></mesh>
        <mesh name="robot0:F1" scale="0.001 0.001 0.001" file="F1.stl"></mesh>
        <mesh name="robot0:lfmetacarpal" scale="0.001 0.001 0.001" file="lfmetacarpal.stl"></mesh>
        <mesh name="robot0:TH3_z" scale="0.001 0.001 0.001" file="TH3_z.stl"></mesh>
        <mesh name="robot0:TH2_z" scale="0.001 0.001 0.001" file="TH2_z.stl"></mesh>
        <mesh name="robot0:TH1_z" scale="0.001 0.001 0.001" file="TH1_z.stl"></mesh>
    </asset>
  
    <worldbody>
        <geom name="floor" type="plane" conaffinity="1" size="100 100 .2" material="floor_mat" />
    <body name="pelvis" pos="0 0 1" childclass="body">
      <freejoint name="root"/>
      <site name="root" class="force-torque"/>
      <geom name="pelvis" type="sphere" pos="0 0 0.07" size=".09" density="2226"/>
      <geom name="upper_waist" type="sphere" pos="0 0 0.205" size="0.07" density="2226"/>
      <site name="pelvis" class="touch" type="sphere" pos="0 0 0.07" size="0.091"/>
      <site name="upper_waist" class="touch" type="sphere" pos="0 0 0.205" size="0.071"/>

      <body name="torso" pos="0 0 0.236151">
        <light name="top" pos="0 0 2" mode="trackcom"/>
        <camera name="back" pos="-3 0 1" xyaxes="0 -1 0 1 0 2" mode="trackcom"/>
        <camera name="side" pos="0 -3 1" xyaxes="1 0 0 0 1 2" mode="trackcom"/>
        <joint name="abdomen_x" pos="0 0 0" axis="1 0 0" range="-1.047 1.047" stiffness="600" damping="60" armature=".025"/>
        <joint name="abdomen_y" pos="0 0 0" axis="0 1 0" range="-1.047 1.57" stiffness="600" damping="60" armature=".025"/>
        <joint name="abdomen_z" pos="0 0 0" axis="0 0 1" range="-0.873 0.873" stiffness="600" damping="60" armature=".025"/>
        <geom name="torso" type="sphere" pos="0 0 0.12" size="0.11" density="1794"/>
        <site name="torso" class="touch" type="sphere" pos="0 0 0.12" size="0.111"/>

        <geom name="right_clavicle" fromto="-0.0060125 -0.0457775 0.2287955 -0.016835 -0.128177 0.2376182" size=".045" density="1100"/>
        <geom name="left_clavicle" fromto="-0.0060125 0.0457775 0.2287955 -0.016835 0.128177 0.2376182" size=".045" density="1100"/>

        <body name="head" pos="0 0 0.223894">
          <joint name="neck_x" axis="1 0 0" range="-0.873 0.873" stiffness="50" damping="5" armature=".017"/>
          <joint name="neck_y" axis="0 1 0" range="-0.698 1.047" stiffness="50" damping="5" armature=".017"/>
          <joint name="neck_z" axis="0 0 1" range="-0.785 0.785" stiffness="50" damping="5" armature=".017"/>
          <geom name="head" type="sphere" pos="0 0 0.175" size="0.095" density="1081"/>
          <site name="head" class="touch" pos="0 0 0.175" type="sphere" size="0.103"/>
          <camera name="egocentric" pos=".103 0 0.175" xyaxes="0 -1 0 .1 0 1" fovy="80"/>
        </body>

        <body name="right_upper_arm" pos="-0.02405 -0.18311 0.24350">
          <joint name="right_shoulder_x" axis="1 0 0" range="-3.142 0.785" stiffness="200" damping="20" armature=".02"/>
          <joint name="right_shoulder_y" axis="0 1 0" range="-3.142 1.047" stiffness="200" damping="20" armature=".02"/>
          <joint name="right_shoulder_z" axis="0 0 1"  range="-1.57 1.57" stiffness="200" damping="20" armature=".02"/>
          <geom name="right_upper_arm" fromto="0 0 -0.05 0 0 -0.23" size=".045" density="982"/>
          <site name="right_upper_arm" class="touch" pos="0 0 -0.14" size="0.046 0.1" zaxis="0 0 1"/>

          <body name="right_lower_arm" pos="0 0 -0.274788">
            <joint name="right_elbow" axis="0 1 0" range="-2.793 0" stiffness="150" damping="15" armature=".015"/>
            <geom name="right_lower_arm" fromto="0 0 -0.0525 0 0 -0.1875" size="0.04" density="1056"/>
            <site name="right_lower_arm" class="touch" pos="0 0 -0.12" size="0.041 0.0685" zaxis="0 1 0"/>

            <body name="right_hand" pos="0 0 -0.258947" quat="0 1 0 0">
                <inertial mass="0.1" pos="0 0 0" diaginertia="0.001 0.001 0.001"/>
                <body childclass="robot0:asset_class" name="robot0:palm" pos="0 0 0" euler="0 0 0">
                    <inertial pos="0.006 0 0.036" quat="0.715833 0.0439898 0.0749825 0.692839" mass="0.3" diaginertia="0.001 0.001 0.001" />
                    <joint name="robot0:WRJ2" type="hinge" pos="0 0 0" axis="0 0 1" range="-0 0.00000001" damping="0.5" armature="0.005" user="1122"/>
                    <joint name="robot0:WRJ1" type="hinge" pos="0 0 0" axis="0 1 0" range="-0.523599 0.174533" damping="0.5" armature="0.005" user="1123"/>
                    <joint name="robot0:WRJ0" type="hinge" pos="0 0 0" axis="1 0 0" range="-0.698132 0.488692" damping="0.5" armature="0.005" user="1122"/>
                    <geom name="robot0:C_palm0" class="robot0:DC_Hand" size="0.032 0.0111 0.049" pos="0.011 0 0.038" type="box" rgba="0.4 0.5 0.6 0.1" />
                    <geom name="robot0:C_palm1" class="robot0:DC_Hand" size="0.011 0.0111 0.025" pos="-0.032 0 0.014" type="box" rgba="0.4 0.5 0.6 0.1" />
                    <body name="robot0:ffknuckle" pos="0.036 -0.004 0.090">
                        <inertial pos="0 0 0" quat="0.520062 0.854102 0.00600072 -0.00300036" mass="0.008" diaginertia="1e-05 1e-05 1e-05" />
                        <joint name="robot0:FFJ3" pos="0 0 0" axis="0 1 0" range="-0.349 0.349" user="1103" />
                        <body name="robot0:ffproximal" pos="0 0 0">
                            <inertial pos="0 0 0.023" quat="0.707095 -0.00400054 0.00400054 0.707095" mass="0.014" diaginertia="1e-05 1e-05 1e-05" />
                            <joint name="robot0:FFJ2" pos="0 0 0" axis="1 0 0" range="0 1.571" user="1102" />
                            <geom name="robot0:C_ffproximal" class="robot0:DC_Hand" size="0.01 0.0175" pos="0 0 0.0175" type="capsule" />
                            <body name="robot0:ffmiddle" pos="0 0 0.035">
                                <inertial pos="0 0 0.011" quat="0.707107 0 0 0.707107" mass="0.012" diaginertia="1e-05 1e-05 1e-05" />
                                <joint name="robot0:FFJ1" pos="0 0 0" axis="1 0 0" range="0 1.571" user="1101" />
                                <geom name="robot0:C_ffmiddle" class="robot0:DC_Hand" size="0.00805 0.0125" pos="0 0 0.0125" type="capsule" />
                                <body name="robot0:ffdistal" pos="0 0 0.025">
                                    <inertial pos="0 0 0.015" quat="0.7071 -0.00300043 0.00300043 0.7071" mass="0.01" diaginertia="1e-05 1e-05 1e-05" />
                                    <joint name="robot0:FFJ0" pos="0 0 0" axis="1 0 0" range="0 1.571" user="1100" />
                                    <geom name="robot0:C_ffdistal" class="robot0:DC_Hand" size="0.00705 0.012" pos="0 0 0.012" type="capsule" condim="4" />
                                    <site name="robot0:S_fftip" pos="0 0 0.026" group="3" />
                                    <site name="robot0:Tch_fftip" class="robot0:D_Touch" pos="0 -0.004 0.018" />
                                </body>
                            </body>
                        </body>
                    </body>
                    <body name="robot0:mfknuckle" pos="0.011 0 0.099">
                        <inertial pos="0 0 0" quat="0.520062 0.854102 0.00600072 -0.00300036" mass="0.008" diaginertia="1e-05 1e-05 1e-05" />
                        <joint name="robot0:MFJ3" pos="0 0 0" axis="0 1 0" range="-0.349 0.349" user="1107" />
                        <body name="robot0:mfproximal" pos="0 0 0">
                            <inertial pos="0 0 0.023" quat="0.707095 -0.00400054 0.00400054 0.707095" mass="0.014" diaginertia="1e-05 1e-05 1e-05" />
                            <joint name="robot0:MFJ2" pos="0 0 0" axis="1 0 0" range="0 1.571" user="1106" />
                            <geom name="robot0:C_mfproximal" class="robot0:DC_Hand" size="0.01 0.0175" pos="0 0 0.0135" type="capsule" />
                            <body name="robot0:mfmiddle" pos="0 0 0.035">
                                <inertial pos="0 0 0.012" quat="0.707107 0 0 0.707107" mass="0.012" diaginertia="1e-05 1e-05 1e-05" />
                                <joint name="robot0:MFJ1" pos="0 0 0" axis="1 0 0" range="0 1.571" user="1105" />
                                <geom name="robot0:C_mfmiddle" class="robot0:DC_Hand" size="0.00805 0.0125" pos="0 0 0.0125" type="capsule" />
                                <body name="robot0:mfdistal" pos="0 0 0.025">
                                    <inertial pos="0 0 0.015" quat="0.7071 -0.00300043 0.00300043 0.7071" mass="0.01" diaginertia="1e-05 1e-05 1e-05" />
                                    <joint name="robot0:MFJ0" pos="0 0 0" axis="1 0 0" range="0 1.571" user="1104" />
                                    <geom name="robot0:C_mfdistal" class="robot0:DC_Hand" size="0.00705 0.012" pos="0 0 0.012" type="capsule" condim="4" />
                                    <site name="robot0:S_mftip" pos="0 0 0.026" group="3" />
                                    <site name="robot0:Tch_mftip" class="robot0:D_Touch" pos="0 -0.004 0.018" />
                                </body>
                            </body>
                        </body>
                    </body>
                    <body name="robot0:rfknuckle" pos="-0.012 -0.004 0.090">
                        <inertial pos="0 0 0" quat="0.520062 0.854102 0.00600072 -0.00300036" mass="0.008" diaginertia="1e-05 1e-05 1e-05" />
                        <joint name="robot0:RFJ3" pos="0 0 0" axis="0 1 0" range="-0.349 0.349" user="1111" />
                        <body name="robot0:rfproximal" pos="0 0 0">
                            <inertial pos="0 0 0.023" quat="0.707095 -0.00400054 0.00400054 0.707095" mass="0.014" diaginertia="1e-05 1e-05 1e-05" />
                            <joint name="robot0:RFJ2" pos="0 0 0" axis="1 0 0" range="0 1.571" user="1110" />
                            <geom name="robot0:C_rfproximal" class="robot0:DC_Hand" size="0.01 0.0175" pos="0 0 0.0175" type="capsule" />
                            <body name="robot0:rfmiddle" pos="0 0 0.033">
                                <inertial pos="0 0 0.012" quat="0.707107 0 0 0.707107" mass="0.012" diaginertia="1e-05 1e-05 1e-05" />
                                <joint name="robot0:RFJ1" pos="0 0 0" axis="1 0 0" range="0 1.571" user="1109" />
                                <geom name="robot0:C_rfmiddle" class="robot0:DC_Hand" size="0.00805 0.0125" pos="0 0 0.0125" type="capsule" />
                                <body name="robot0:rfdistal" pos="0 0 0.025">
                                    <inertial pos="0 0 0.015" quat="0.7071 -0.00300043 0.00300043 0.7071" mass="0.01" diaginertia="1e-05 1e-05 1e-05" />
                                    <joint name="robot0:RFJ0" pos="0 0 0" axis="1 0 0" range="0 1.571" user="1108" />
                                    <geom name="robot0:C_rfdistal" class="robot0:DC_Hand" size="0.00705 0.012" pos="0 0 0.012" type="capsule" condim="4" />
                                    <site name="robot0:S_rftip" pos="0 0 0.026" group="3" />
                                    <site name="robot0:Tch_rftip" class="robot0:D_Touch" pos="0 -0.004 0.018" />
                                </body>
                            </body>
                        </body>
                    </body>
                    <body name="robot0:lfmetacarpal" pos="-0.017 0 0.044">
                        <inertial pos="-0.014 0.001 0.014" quat="0.709167 -0.0920216 -0.0630148 0.696164" mass="0.075" diaginertia="1e-05 1e-05 1e-05" />
                        <joint name="robot0:LFJ4" pos="0 0 0" axis="0.570977 0 0.820966" range="0 0.785" user="1116" />
                        <geom name="robot0:C_lfmetacarpal" class="robot0:DC_Hand" size="0.0095 0.0111 0.025" pos="-0.0165 0 0.01" type="box" rgba="0.4 0.5 0.6 0.2" />
                        <body name="robot0:lfknuckle" pos="-0.017 -0.008 0.035">
                            <inertial pos="0 0 0" quat="0.520062 0.854102 0.00600072 -0.00300036" mass="0.008" diaginertia="1e-05 1e-05 1e-05" />
                            <joint name="robot0:LFJ3" pos="0 0 0" axis="0 1 0" range="-0.45 0.349" user="1115" />
                            <body name="robot0:lfproximal" pos="0 0 0">
                                <inertial pos="0 0 0.023" quat="0.707095 -0.00400054 0.00400054 0.707095" mass="0.014" diaginertia="1e-05 1e-05 1e-05" />
                                <joint name="robot0:LFJ2" pos="0 0 0" axis="1 0 0" range="0 1.571" user="1114" />
                                <geom name="robot0:C_lfproximal" class="robot0:DC_Hand" size="0.01 0.0138" pos="0 0 0.0175" type="capsule" />
                                <body name="robot0:lfmiddle" pos="0 0 0.025">
                                    <inertial pos="0 0 0.012" quat="0.707107 0 0 0.707107" mass="0.012" diaginertia="1e-05 1e-05 1e-05" />
                                    <joint name="robot0:LFJ1" pos="0 0 0" axis="1 0 0" range="0 1.571" user="1113" />
                                    <geom name="robot0:C_lfmiddle" class="robot0:DC_Hand" size="0.00805 0.0125" pos="0 0 0.0125" type="capsule" />
                                    <body name="robot0:lfdistal" pos="0 0 0.020">
                                        <inertial pos="0 0 0.015" quat="0.7071 -0.00300043 0.00300043 0.7071" mass="0.01" diaginertia="1e-05 1e-05 1e-05" />
                                        <joint name="robot0:LFJ0" pos="0 0 0" axis="1 0 0" range="0 1.571" user="1112" />
                                        <geom name="robot0:C_lfdistal" class="robot0:DC_Hand" size="0.00705 0.012" pos="0 0 0.012" type="capsule" condim="4" />
                                        <site name="robot0:S_lftip" pos="0 0 0.026" group="3" />
                                        <site name="robot0:Tch_lftip" class="robot0:D_Touch" pos="0 -0.004 0.018" />
                                    </body>
                                </body>
                            </body>
                        </body>
                    </body>
                    <body name="robot0:thbase" pos="0.031 -0.017 0.023" quat="0.923956 0 0.382499 0">
                        <inertial pos="0 0 0" mass="0.01" diaginertia="1e-05 1e-05 1e-05" />
                        <joint name="robot0:THJ4" pos="0 0 0" axis="0 0 -1" range="-1.047 1.047" user="1121" />
                        <geom name="robot0:V_thbase" size="0.001 0.001 0.001" type="box" group="1" />
                        <body name="robot0:thproximal" pos="0 0 0">
                            <inertial pos="0 0 0.017" quat="0.981604 0 0.000999597 0.190923" mass="0.016" diaginertia="1e-05 1e-05 1e-05" />
                            <joint name="robot0:THJ3" pos="0 0 0" axis="1 0 0" range="0 1.222" user="1120" />
                            <geom name="robot0:C_thproximal" class="robot0:DC_Hand" size="0.013 0.019" pos="0 0 0.019" type="capsule" rgba="0.4 0.5 0.6 0.1" />
                            <body name="robot0:thhub" pos="0 0 0.032">
                                <inertial pos="0 0 0" mass="0.002" diaginertia="1e-05 1e-05 1e-05" />
                                <joint name="robot0:THJ2" pos="0 0 0" axis="1 0 0" range="-0.209 0.209" user="1119" />
                                <geom name="robot0:V_thhub" size="0.001 0.001 0.001" type="box" group="1" />
                                <body name="robot0:thmiddle" pos="0 0 0">
                                    <inertial pos="0 0 0.016" quat="0.999971 -0.000999971 -0.00699979 0.00299991" mass="0.016" diaginertia="1e-05 1e-05 1e-05" />
                                    <joint name="robot0:THJ1" pos="0 0 0" axis="0 1 0" range="-0.524 0.524" user="1118" />
                                    <geom name="robot0:C_thmiddle" class="robot0:DC_Hand" size="0.011 0.016" pos="0 0 0.016" type="capsule" />
                                    <body name="robot0:thdistal" pos="0 -0.004 0.028">
                                        <inertial pos="0 0 0.016" quat="0.99887 -0.00499935 -0.0469939 0.00499935" mass="0.016" diaginertia="1e-05 1e-05 1e-05" />
                                        <joint name="robot0:THJ0" pos="0 0 0" axis="0 1 0" range="-1.571 0" user="1117" />
                                        <geom name="robot0:C_thdistal" class="robot0:DC_Hand" size="0.00918 0.013" pos="0 0.004 0.013" type="capsule" condim="4" />
                                        <site name="robot0:S_thtip" pos="0 0.004 0.0275" group="3" />
                                        <site name="robot0:Tch_thtip" class="robot0:D_Touch" pos="-0.005 0 0.02" size="0.005 0.011 0.016" />
                                    </body>
                                </body>
                            </body>
                        </body>
                    </body>
                </body>
            </body>

          </body>
        </body>

        <body name="left_upper_arm" pos="-0.02405 0.18311 0.24350">
          <joint name="left_shoulder_x" axis="1 0 0" range="-0.783 3.142" stiffness="200" damping="20" armature=".02"/>
          <joint name="left_shoulder_y" axis="0 1 0" range="-3.142 1.047" stiffness="200" damping="20" armature=".02"/>
          <joint name="left_shoulder_z" axis="0 0 1"  range="-1.57 1.57" stiffness="200" damping="20" armature=".02"/>
          <geom name="left_upper_arm" fromto="0 0 -0.05 0 0 -0.23" size="0.045" density="982"/>
          <site name="left_upper_arm" class="touch" pos="0 0 -0.14" size="0.046 0.1" zaxis="0 0 1"/>

          <body name="left_lower_arm" pos="0 0 -0.274788">
            <joint name="left_elbow" axis="0 1 0" range="-2.793 0" stiffness="150" damping="15" armature=".015"/>
            <geom name="left_lower_arm" fromto="0 0 -0.0525 0 0 -0.1875" size="0.04" density="1056"/>
            <site name="left_lower_arm" class="touch" pos="0 0 -0.1" size="0.041 0.0685" zaxis="0 0 1"/>


            <body name="left_hand" pos="0 0 -0.258947" quat="0 1 0 0">
                <site name="left_hand" class="touch" type="sphere" size=".041"/>
                <geom name="robot0:C_palm0_l" class="robot0:DC_Hand" size="0.032 0.0111 0.049" pos="0.011 0 0.038" type="box" rgba="0.4 0.5 0.6 0.1" />
                <geom name="robot0:C_palm1_l" class="robot0:DC_Hand" size="0.011 0.0111 0.025" pos="-0.032 0 0.014" type="box" rgba="0.4 0.5 0.6 0.1" />
                <geom name="robot0:C_ffproximal_l" class="robot0:DC_Hand" size="0.01 0.0175" pos="0.036 0.004 0.1075" type="capsule" />
                <geom name="robot0:C_ffmiddle_l" class="robot0:DC_Hand" size="0.00805 0.0125" pos="0.036 0.004 0.1375" type="capsule" />
                <geom name="robot0:C_ffdistal_l" class="robot0:DC_Hand" size="0.00705 0.012" pos="0.036 0.004 0.162" type="capsule" condim="4" />
                
                <geom name="robot0:C_mfproximal_l" class="robot0:DC_Hand" size="0.01 0.0175" pos="0.011 0 0.1125" type="capsule" />
                <geom name="robot0:C_mfmiddle_l" class="robot0:DC_Hand" size="0.00805 0.0125" pos="0.011 0 0.1465" type="capsule" />
                <geom name="robot0:C_mfdistal_l" class="robot0:DC_Hand" size="0.00705 0.012" pos="0.011 0 0.171" type="capsule" condim="4" />
                        
                <geom name="robot0:C_rfproximal_l" class="robot0:DC_Hand" size="0.01 0.0175" pos="-0.012 0.004 0.1075" type="capsule" />
                <geom name="robot0:C_rfmiddle_l" class="robot0:DC_Hand" size="0.00805 0.0125" pos="-0.012 0.004 0.1355" type="capsule" />
                <geom name="robot0:C_rfdistal_l" class="robot0:DC_Hand" size="0.00705 0.012" pos="-0.012 0.004 0.16" type="capsule" condim="4" />
                              
                <geom name="robot0:C_lfmetacarpal_l" class="robot0:DC_Hand" size="0.0095 0.0111 0.025" pos="-0.0335 0 0.054" type="box" rgba="0.4 0.5 0.6 0.2" />
                <geom name="robot0:C_lfproximal_l" class="robot0:DC_Hand" size="0.01 0.0138" pos="-0.034 0.008 0.0965" type="capsule" />
                <geom name="robot0:C_lfmiddle_l" class="robot0:DC_Hand" size="0.00805 0.0125" pos="-0.034 0.008 0.1165" type="capsule" />
                <geom name="robot0:C_lfdistal_l" class="robot0:DC_Hand" size="0.00705 0.012" pos="-0.034 0.008 0.136" type="capsule" condim="4" />
                    
                <geom name="robot0:C_thproximal_l" class="robot0:DC_Hand" size="0.013 0.019" pos="0.044 0.017 0.036" type="capsule" rgba="0.4 0.5 0.6 0.1" quat="0.923956 0 0.382499 0"/>
                <geom name="robot0:C_thmiddle_l" class="robot0:DC_Hand" size="0.011 0.016" pos="0.065 0.017 0.057" type="capsule" quat="0.923956 0 0.382499 0"/>
                <geom name="robot0:C_thdistal_l" class="robot0:DC_Hand" size="0.00918 0.013" pos="0.082 0.017 0.075" type="capsule" condim="4" quat="0.923956 0 0.382499 0"/>
            </body>
          </body>
        </body>
      </body>

      <body name="right_thigh" pos="0 -0.084887 0">
        <site name="right_hip" class="force-torque"/>
        <joint name="right_hip_x" axis="1 0 0" range="-1.047 0.262" stiffness="300" damping="30" armature=".02"/>
        <joint name="right_hip_y" axis="0 1 0" range="-2.443 1.047" stiffness="300" damping="30" armature=".02"/>
        <joint name="right_hip_z" axis="0 0 1" range="-1.047 0.611" stiffness="300" damping="30" armature=".02"/>
        <geom name="right_thigh" fromto="0 0 -0.06 0 0 -0.36" size="0.055" density="1269"/>
        <site name="right_thigh" class="touch" pos="0 0 -0.21" size="0.056 0.301" zaxis="0 0 -1"/>

        <body name="right_shin" pos="0 0 -0.421546">
          <site name="right_knee" class="force-torque" pos="0 0 0"/>
          <joint name="right_knee" pos="0 0 0" axis="0 1 0" range="0 2.793" stiffness="300" damping="30" armature=".02"/>
          <geom name="right_shin" fromto="0 0 -0.045 0 0 -0.355"  size=".05" density="1014"/>
          <site name="right_shin" class="touch" pos="0 0 -0.2" size="0.051 0.156" zaxis="0 0 -1"/>

          <body name="right_foot" pos="0 0 -0.409870">
            <site name="right_ankle" class="force-torque"/>
            <joint name="right_ankle_x" pos="0 0 0" axis="1 0 0" range="-0.524 0.524" stiffness="200" damping="20" armature=".01"/>
            <joint name="right_ankle_y" pos="0 0 0" axis="0 1 0" range="-0.960 0.960" stiffness="200" damping="20" armature=".01"/>
            <joint name="right_ankle_z" pos="0 0 0" axis="0 0 1" range="-0.698 0.698" stiffness="200" damping="20" armature=".01"/>
            <geom name="right_foot" type="box" pos="0.045 0 -0.0225" size="0.0885 0.045 0.0275" density="1141"/>
            <site name="right_foot" class="touch" type="box" pos="0.045 0 -0.0225" size="0.0895 0.055 0.0285"/>
          </body>
        </body>
      </body>

      <body name="left_thigh" pos="0 0.084887 0">
        <site name="left_hip" class="force-torque"/>
        <joint name="left_hip_x" axis="1 0 0" range="-0.262 1.047" stiffness="300" damping="30" armature=".02"/>
        <joint name="left_hip_y" axis="0 1 0" range="-2.443 1.047" stiffness="300" damping="30" armature=".02"/>
        <joint name="left_hip_z" axis="0 0 1" range="-0.611 1.047" stiffness="300" damping="30" armature=".02"/>
        <geom name="left_thigh" fromto="0 0 -0.06 0 0 -0.36" size=".055" density="1269"/>
        <site name="left_thigh" class="touch" pos="0 0 -0.21" size="0.056 0.301" zaxis="0 0 -1"/>

        <body name="left_shin" pos="0 0 -0.421546">
          <site name="left_knee" class="force-torque" pos="0 0 .02"/>
          <joint name="left_knee" pos="0 0 0" axis="0 1 0" range="0 2.793" stiffness="300" damping="30" armature=".02"/>
          <geom name="left_shin" fromto="0 0 -0.045 0 0 -0.355"  size=".05" density="1014"/>
          <site name="left_shin" class="touch" pos="0 0 -0.2" size="0.051 0.156" zaxis="0 0 -1"/>

          <body name="left_foot" pos="0 0 -0.409870">
            <site name="left_ankle" class="force-torque"/>
            <joint name="left_ankle_x" pos="0 0 0" axis="1 0 0" range="-0.524 0.524" stiffness="200" damping="20" armature=".01"/>
            <joint name="left_ankle_y" pos="0 0 0" axis="0 1 0" range="-0.960 0.960" stiffness="200" damping="20" armature=".01"/>
            <joint name="left_ankle_z" pos="0 0 0" axis="0 0 1" range="-0.698 0.698" stiffness="200" damping="20" armature=".01"/>
            <geom name="left_foot" type="box" pos="0.045 0 -0.0225" size="0.0885 0.045 0.0275" density="1141"/>
            <site name="left_foot" class="touch" type="box" pos="0.045 0 -0.0225" size="0.0895 0.055 0.0285"/>
          </body>
        </body>
      </body>
    </body>

        
        <light directional="true" ambient="0.2 0.2 0.2" diffuse="0.8 0.8 0.8" specular="0.3 0.3 0.3" castshadow="false" pos="0 1 4" dir="0 0 -1" name="light0"></light>
    </worldbody>
</mujoco>
