<mujoco model="humanoid">
  <compiler angle="radian" coordinate="local" meshdir="../stls/hand" texturedir="../textures"></compiler>
  <statistic extent="2" center="0 0 1"/>
  <option timestep="0.00555" iterations="20" apirate="200">
        <flag warmstart="enable"></flag>
  </option>
  <default>
    <motor ctrlrange="-1 1" ctrllimited="true"/>
    <geom type="capsule" condim="1" friction="1.0 0.05 0.05" solimp=".9 .99 .003" solref=".015 1"/>
    <joint type="hinge" damping="0.1" stiffness="5" armature=".007" limited="true" solimplimit="0 .99 .01"/>
    <site size=".04" group="3"/>
    <default class="force-torque">
      <site type="box" size=".01 .01 .02" rgba="1 0 0 1"/>
    </default>
    <default class="touch">
      <site type="capsule" rgba="0 0 1 .3"/>
    </default>

    <default class="robot0:asset_class">
            <geom friction="1 0.005 0.001" condim="3" margin="0.0005" contype="1" conaffinity="1"></geom>
            <joint limited="true" damping="0.1" armature="0.001" margin="0.01" frictionloss="0.001"></joint>
            <site size="0.005" rgba="0.4 0.9 0.4 1"></site>
            <general ctrllimited="true" forcelimited="true"></general>
    </default>
    <default class="robot0:D_Touch">
        <site type="box" size="0.009 0.004 0.013" pos="0 -0.004 0.018" rgba="0.8 0.8 0.8 0.15" group="4"></site>
    </default>
    <default class="robot0:DC_Hand">
        <geom material="robot0:MatColl" contype="1" conaffinity="0" group="4"></geom>
    </default>
    <default class="robot0:D_Vizual">
        <geom material="robot0:MatViz" contype="0" conaffinity="0" group="1" type="mesh"></geom>
    </default>
    <default class="robot0:free">
        <joint type="free" damping="0" armature="0" limited="false"></joint>
    </default>
  </default>

  <size njmax="500" nconmax="100" nuser_jnt="1" nuser_site="1" nuser_tendon="1" nuser_sensor="1" nuser_actuator="16" nstack="600000"></size>

  <visual>
      <map fogstart="3" fogend="5" force="0.1"></map>
      <quality shadowsize="4096"></quality>
  </visual>

  <asset>
    <texture type="skybox" builtin="gradient" rgb1=".4 .5 .6" rgb2="0 0 0" width="100" height="100"/>
    <texture builtin="flat" height="1278" mark="cross" markrgb="1 1 1" name="texgeom" random="0.01" rgb1="0.8 0.6 0.4" rgb2="0.8 0.6 0.4" type="cube" width="127"/>
    <texture builtin="checker" height="100" name="texplane" rgb1="0 0 0" rgb2="0.8 0.8 0.8" type="2d" width="100"/>
    <material name="MatPlane" reflectance="0.5" shininess="1" specular="1" texrepeat="60 60" texture="texplane"/>
    <material name="geom" texture="texgeom" texuniform="true"/>

    <texture name="robot0:texplane" type="2d" builtin="checker" rgb1="0.2 0.3 0.4" rgb2="0.1 0.15 0.2" width="512" height="512"></texture>
    <texture name="robot0:texgeom" type="cube" builtin="flat" mark="cross" width="127" height="127" rgb1="0.3 0.6 0.5" rgb2="0.3 0.6 0.5" markrgb="0 0 0" random="0.01"></texture>

    <material name="robot0:MatGnd" reflectance="0.5" texture="robot0:texplane" texrepeat="1 1" texuniform="true"></material>
    <material name="robot0:MatColl" specular="1" shininess="0.3" reflectance="0.5" rgba="0.4 0.5 0.6 1"></material>
    <material name="robot0:MatViz" specular="0.75" shininess="0.1" reflectance="0.5" rgba="0.93 0.93 0.93 1"></material>
    <material name="robot0:object" texture="robot0:texgeom" texuniform="false"></material>
    <material name="floor_mat" specular="0" shininess="0.5" reflectance="0" rgba="0.2 0.2 0.2 0"></material>

    <mesh name="robot0:palm" scale="0.001 0.001 0.001" file="palm.stl"></mesh>
    <mesh name="robot0:knuckle" scale="0.001 0.001 0.001" file="knuckle.stl"></mesh>
    <mesh name="robot0:F3" scale="0.001 0.001 0.001" file="F3.stl"></mesh>
    <mesh name="robot0:F2" scale="0.001 0.001 0.001" file="F2.stl"></mesh>
    <mesh name="robot0:F1" scale="0.001 0.001 0.001" file="F1.stl"></mesh>
    <mesh name="robot0:lfmetacarpal" scale="0.001 0.001 0.001" file="lfmetacarpal.stl"></mesh>
    <mesh name="robot0:TH3_z" scale="0.001 0.001 0.001" file="TH3_z.stl"></mesh>
    <mesh name="robot0:TH2_z" scale="0.001 0.001 0.001" file="TH2_z.stl"></mesh>
    <mesh name="robot0:TH1_z" scale="0.001 0.001 0.001" file="TH1_z.stl"></mesh>
  </asset>

  <tendon>
      <fixed name="robot0:T_FFJ1c" limited="true" range="-0.001 0.001">
          <joint joint="robot0:FFJ0" coef="0.00705"></joint>
          <joint joint="robot0:FFJ1" coef="-0.00805"></joint>
      </fixed>
      <fixed name="robot0:T_MFJ1c" limited="true" range="-0.001 0.001">
          <joint joint="robot0:MFJ0" coef="0.00705"></joint>
          <joint joint="robot0:MFJ1" coef="-0.00805"></joint>
      </fixed>
      <fixed name="robot0:T_RFJ1c" limited="true" range="-0.001 0.001">
          <joint joint="robot0:RFJ0" coef="0.00705"></joint>
          <joint joint="robot0:RFJ1" coef="-0.00805"></joint>
      </fixed>
      <fixed name="robot0:T_LFJ1c" limited="true" range="-0.001 0.001">
          <joint joint="robot0:LFJ0" coef="0.00705"></joint>
          <joint joint="robot0:LFJ1" coef="-0.00805"></joint>
      </fixed>
  </tendon>

  <contact>
    <pair geom1="robot0:C_ffdistal" geom2="robot0:C_thdistal" condim="1"></pair>
    <pair geom1="robot0:C_ffmiddle" geom2="robot0:C_thdistal" condim="1"></pair>
    <pair geom1="robot0:C_ffproximal" geom2="robot0:C_thdistal" condim="1"></pair>
    <pair geom1="robot0:C_mfproximal" geom2="robot0:C_thdistal" condim="1"></pair>
    <pair geom1="robot0:C_mfdistal" geom2="robot0:C_thdistal" condim="1"></pair>
    <pair geom1="robot0:C_rfdistal" geom2="robot0:C_thdistal" condim="1"></pair>
    <pair geom1="robot0:C_lfdistal" geom2="robot0:C_thdistal" condim="1"></pair>
    <pair geom1="robot0:C_palm0" geom2="robot0:C_thdistal" condim="1"></pair>
    <pair geom1="robot0:C_mfdistal" geom2="robot0:C_ffdistal" condim="1"></pair>
    <pair geom1="robot0:C_rfdistal" geom2="robot0:C_mfdistal" condim="1"></pair>
    <pair geom1="robot0:C_lfdistal" geom2="robot0:C_rfdistal" condim="1"></pair>
    <pair geom1="robot0:C_mfproximal" geom2="robot0:C_ffproximal" condim="1"></pair>
    <pair geom1="robot0:C_rfproximal" geom2="robot0:C_mfproximal" condim="1"></pair>
    <pair geom1="robot0:C_lfproximal" geom2="robot0:C_rfproximal" condim="1"></pair>
    <pair geom1="robot0:C_lfdistal" geom2="robot0:C_rfdistal" condim="1"></pair>
    <pair geom1="robot0:C_lfdistal" geom2="robot0:C_mfdistal" condim="1"></pair>
    <pair geom1="robot0:C_lfdistal" geom2="robot0:C_rfmiddle" condim="1"></pair>
    <pair geom1="robot0:C_lfmiddle" geom2="robot0:C_rfdistal" condim="1"></pair>
    <pair geom1="robot0:C_lfmiddle" geom2="robot0:C_rfmiddle" condim="1"></pair>
  </contact>
  <worldbody>
    <light cutoff="100" diffuse="1 1 1" dir="-0 0 -1.3" directional="true" exponent="1" pos="0 0 1.3" specular=".1 .1 .1"/>
    <geom conaffinity="1" condim="3" name="floor" pos="0 0 0" rgba="0.8 0.9 0.8 1" size="100 100 .2" type="plane" material="MatPlane"/>
    <!-- <body name="Pelvis" pos="-0.0018 -0.2233 0.0282"> -->
    <body name="Pelvis" pos="0 0 0.94">
      <freejoint name="Pelvis"/>
      <geom type="sphere" contype="1" conaffinity="1" density="4629.6296296296305" size="0.0942" pos="0.0000 0.0000 0.0000"/>
      <body name="L_Hip" pos="-0.0068 0.0695 -0.0914">
        <joint name="L_Hip_x" type="hinge" pos="0 0 0" axis="1 0 0" stiffness="500" damping="50" armature="0.02" range="-0.26 1.0472"/>
        <joint name="L_Hip_y" type="hinge" pos="0 0 0" axis="0 1 0" stiffness="500" damping="50" armature="0.02" range="-2.443 1.0472"/>
        <joint name="L_Hip_z" type="hinge" pos="0 0 0" axis="0 0 1" stiffness="500" damping="50" armature="0.02" range="-0.611 1.0472"/>
        <geom type="capsule" contype="1" conaffinity="1" density="2040.816327" fromto="-0.0009 0.0069 -0.0750 -0.0036 0.0274 -0.3002" size="0.0615"/>
        <body name="L_Knee" pos="-0.0045 0.0343 -0.3752">
          <joint name="L_Knee_y" type="hinge" pos="0 0 0" axis="0 1 0" stiffness="500" damping="50" armature="0.02" range="0 2.793"/>
          <geom type="capsule" contype="1" conaffinity="1" density="1234.567901" fromto="-0.0087 -0.0027 -0.0796 -0.0350 -0.0109 -0.3184" size="0.0541"/>
          <body name="L_Ankle" pos="-0.0437 -0.0136 -0.398">
            <joint name="L_Ankle_x" type="hinge" pos="0 0 0" axis="1 0 0" stiffness="400" damping="40" armature="0.02" range="-0.524 0.524"/>
            <joint name="L_Ankle_y" type="hinge" pos="0 0 0" axis="0 1 0" stiffness="400" damping="40" armature="0.02" range="-0.96 0.96"/>
            <joint name="L_Ankle_z" type="hinge" pos="0 0 0" axis="0 0 1" stiffness="400" damping="40" armature="0.02" range="-0.70 0.70"/>
            <geom type="box" pos="0.0242 0.0233 -0.0239" size="0.085 0.0483 0.0464" quat="1.0000 0.0000 0.0000 0.0000"/>
            <body name="L_Toe" pos="0.1193 0.0264 -0.0558">
              <joint name="L_Toe_y" type="hinge" pos="0 0 0" axis="0 1 0" stiffness="200" damping="20" armature="0.02" range="-0.524 0"/>
              <geom type="box" pos="0.0248 -0.0030 0.0055" size="0.0496 0.0478 0.02" quat="1.0000 0.0000 0.0000 0.0000"/>
            </body>
          </body>
        </body>
      </body>
      <body name="R_Hip" pos="-0.0043 -0.0677 -0.0905">
        <joint name="R_Hip_x" type="hinge" pos="0 0 0" axis="1 0 0" stiffness="500" damping="50" armature="0.02" range="-1.047 0.262"/>
        <joint name="R_Hip_y" type="hinge" pos="0 0 0" axis="0 1 0" stiffness="500" damping="50" armature="0.02" range="-2.443 1.047"/>
        <joint name="R_Hip_z" type="hinge" pos="0 0 0" axis="0 0 1" stiffness="500" damping="50" armature="0.02" range="-1.047 0.611"/>
        <geom type="capsule" contype="1" conaffinity="1" density="2040.816327" fromto="-0.0018 -0.0077 -0.0765 -0.0071 -0.0306 -0.3061" size="0.0606"/>
        <body name="R_Knee" pos="-0.0089 -0.0383 -0.3826">
          <joint name="R_Knee_y" type="hinge" pos="0 0 0" axis="0 1 0" stiffness="500" damping="50" armature="0.02" range="0 2.793"/>
          <geom type="capsule" contype="1" conaffinity="1" density="1234.567901" fromto="-0.0085 0.0032 -0.0797 -0.0338 0.0126 -0.3187" size="0.0541"/>
          <body name="R_Ankle" pos="-0.0423 0.0158 -0.3984">
            <joint name="R_Ankle_x" type="hinge" pos="0 0 0" axis="1 0 0" stiffness="400" damping="40" armature="0.02" range="-0.524 0.524"/>
            <joint name="R_Ankle_y" type="hinge" pos="0 0 0" axis="0 1 0" stiffness="400" damping="40" armature="0.02" range="-0.96 0.96"/>
            <joint name="R_Ankle_z" type="hinge" pos="0 0 0" axis="0 0 1" stiffness="400" damping="40" armature="0.02" range="-0.70 0.70"/>
            <geom type="box" pos="0.0256 -0.0212 -0.0174" size="0.0865 0.0483 0.0478" quat="1.0000 0.0000 0.0000 0.0000"/>
            <body name="R_Toe" pos="0.1233 -0.0254 -0.0481">
              <joint name="R_Toe_y" type="hinge" pos="0 0 0" axis="0 1 0" stiffness="200" damping="20" armature="0.02" range="-0.524 0"/>
              <geom type="box" pos="0.0227 0.0042 0.0045" size="0.0493 0.0479 0.0216" quat="1.0000 0.0000 0.0000 0.0000"/>
            </body>
          </body>
        </body>
      </body>
      <body name="Torso" pos="-0.0267 -0.0025 0.109">
        <geom type="capsule" contype="1" conaffinity="1" density="2040.816327" fromto="0.0005 0.0025 0.0608 0.0006 0.0030 0.0743" size="0.0769"/>
        <body name="Spine" pos="0.0011 0.0055 0.1352">
          <joint name="Spine_x" type="hinge" pos="0 0 0" axis="1 0 0" stiffness="1000" damping="100" armature="0.02" range="-1.047 1.047"/>
          <joint name="Spine_y" type="hinge" pos="0 0 0" axis="0 1 0" stiffness="1000" damping="100" armature="0.02" range="-0.175 1.571"/>
          <joint name="Spine_z" type="hinge" pos="0 0 0" axis="0 0 1" stiffness="1000" damping="100" armature="0.02" range="-0.873 0.873"/>
          <geom type="capsule" contype="1" conaffinity="1" density="2040.816327" fromto="0.0114 0.0007 0.0238 0.0140 0.0008 0.0291" size="0.0755"/>
          <body name="Chest" pos="0.0254 0.0015 0.0529">
            <geom type="capsule" contype="1" conaffinity="1" density="2040.816327" fromto="-0.0173 -0.0009 0.0682 -0.0212 -0.0010 0.0833" size="0.1002"/>
            <body name="Neck" pos="-0.0429 -0.0028 0.2139">
              <joint name="Neck_x" type="hinge" pos="0 0 0" axis="1 0 0" stiffness="100" damping="10" armature="0.02" range="-0.873 0.873"/>
              <joint name="Neck_y" type="hinge" pos="0 0 0" axis="0 1 0" stiffness="100" damping="10" armature="0.02" range="-0.70 1.047"/>
              <joint name="Neck_z" type="hinge" pos="0 0 0" axis="0 0 1" stiffness="100" damping="10" armature="0.02" range="-0.785 0.785"/>
              <geom type="capsule" contype="1" conaffinity="1" density="1000" fromto="0.0103 0.0010 0.0130 0.0411 0.0041 0.0520" size="0.0436"/>
              <body name="Head" pos="0.0513 0.0052 0.065">
                <geom type="sphere" contype="1" conaffinity="1" density="1000" size="0.1011" pos="0.0000 0.0000 0.0000"/>
              </body>
            </body>
            <body name="L_Thorax" pos="-0.0341 0.0788 0.1217">
              <joint name="L_Thorax_x" type="hinge" pos="0 0 0" axis="1 0 0" stiffness="400" damping="40" armature="0.02" range="-0.70 0"/>
              <geom type="capsule" contype="1" conaffinity="1" density="1000" fromto="-0.0018 0.0182 0.0061 -0.0071 0.0728 0.0244" size="0.0521"/>
              <body name="L_Shoulder" pos="-0.0089 0.091 0.0305">
                <joint name="L_Shoulder_x" type="hinge" pos="0 0 0" axis="1 0 0" stiffness="400" damping="40" armature="0.02" range="-3.141 0.785"/>
                <joint name="L_Shoulder_y" type="hinge" pos="0 0 0" axis="0 1 0" stiffness="400" damping="40" armature="0.02" range="-3.141 1.047"/>
                <joint name="L_Shoulder_z" type="hinge" pos="0 0 0" axis="0 0 1" stiffness="400" damping="40" armature="0.02" range="-1.57 1.57"/>
                <geom type="capsule" contype="1" conaffinity="1" density="1000" fromto="-0.0055 0.0519 -0.0026 -0.0220 0.2077 -0.0102" size="0.0517"/>
                <body name="L_Elbow" pos="-0.0275 0.2596 -0.0128">
                  <joint name="L_Elbow_x" type="hinge" pos="0 0 0" axis="1 0 0" stiffness="300" damping="30" armature="0.02" range="-2.79 0"/>
                  <geom type="capsule" contype="1" conaffinity="1" density="1000" fromto="-0.0002 0.0498 0.0018 -0.0009 0.1994 0.0072" size="0.0405"/>
                  <body name="L_Wrist" pos="-0.0012 0.2492 0.009">
                    <geom type="capsule" contype="1" conaffinity="1" density="1000" fromto="-0.0007 0.0175 -0.0023 -0.0029 0.0699 -0.0092" size="0.0291"/>
                    <body name="L_Hand" pos="0 0.084 -0.009">
                      <geom type="sphere" contype="1" conaffinity="1" density="1000" size="0.0337" pos="0.0000 0.0000 0.0000"/>
                    </body>

                  </body>
                </body>
              </body>
            </body>
            <body name="R_Thorax" pos="-0.0386 -0.0818 0.1188">
              <joint name="R_Thorax_x" type="hinge" pos="0 0 0" axis="1 0 0" stiffness="400" damping="40" armature="0.02" range="0 0.70 "/>
              <geom type="capsule" contype="1" conaffinity="1" density="1000" fromto="-0.0018 -0.0192 0.0065 -0.0073 -0.0768 0.0260" size="0.0511"/>
              <body name="R_Shoulder" pos="-0.0091 -0.096 0.0326">
                <joint name="R_Shoulder_x" type="hinge" pos="0 0 0" axis="1 0 0" stiffness="400" damping="40" armature="0.02" range="-3.14 0.785"/>
                <joint name="R_Shoulder_y" type="hinge" pos="0 0 0" axis="0 1 0" stiffness="400" damping="40" armature="0.02" range="-3.14 1.047"/>
                <joint name="R_Shoulder_z" type="hinge" pos="0 0 0" axis="0 0 1" stiffness="400" damping="40" armature="0.02" range="-1.57 1.57"/>
                <geom type="capsule" contype="1" conaffinity="1" density="1000" fromto="-0.0043 -0.0507 -0.0027 -0.0171 -0.2030 -0.0107" size="0.0531"/>
                <body name="R_Elbow" pos="-0.0214 -0.2537 -0.0133">
                  <joint name="R_Elbow_x" type="hinge" pos="0 0 0" axis="1 0 0" stiffness="300" damping="30" armature="0.02" range="0 2.79"/>
                  <geom type="capsule" contype="1" conaffinity="1" density="1000" fromto="-0.0011 -0.0511 0.0016 -0.0044 -0.2042 0.0062" size="0.0408"/>
                  <body name="R_Wrist" pos="-0.0056 -0.2553 0.0078">
                    <geom type="capsule" contype="1" conaffinity="1" density="1000" fromto="-0.0003 -0.0169 -0.0022 -0.0011 -0.0677 -0.0090" size="0.03"/>
                    
                  <body name="robot0:hand mount" pos="-0.0103 -0.0846 -0.0061" quat="0.707 0.707 0 0">
                    <inertial mass="0.1" pos="0 0 0" diaginertia="0.001 0.001 0.001"/>
                    <body childclass="robot0:asset_class" name="robot0:palm" pos="0 0 0" euler="0 0 0">
                        <inertial pos="0.006 0 0.036" quat="0.715833 0.0439898 0.0749825 0.692839" mass="0.3" diaginertia="0.001 0.001 0.001" />
                        <joint name="robot0:WRJ2" type="hinge" pos="0 0 0" axis="0 0 1" range="-1.57 1.57" damping="0.5" armature="0.005" user="1122"/>
                        <joint name="robot0:WRJ1" type="hinge" pos="0 0 0" axis="0 1 0" range="-0.489 0.14" damping="0.5" armature="0.005" user="1123"/>
                        <joint name="robot0:WRJ0" type="hinge" pos="0 0 0" axis="1 0 0" range="-0.698 0.489" damping="0.5" armature="0.005" user="1122"/>
                        <geom name="robot0:C_palm0" class="robot0:DC_Hand" size="0.032 0.0111 0.049" pos="0.011 0 0.038" type="box" rgba="0.4 0.5 0.6 0.1" />
                        <geom name="robot0:C_palm1" class="robot0:DC_Hand" size="0.011 0.0111 0.025" pos="-0.032 0 0.014" type="box" rgba="0.4 0.5 0.6 0.1" />
                        <body name="robot0:ffknuckle" pos="0.036 -0.004 0.090">
                            <inertial pos="0 0 0" quat="0.520062 0.854102 0.00600072 -0.00300036" mass="0.008" diaginertia="1e-05 1e-05 1e-05" />
                            <joint name="robot0:FFJ3" pos="0 0 0" axis="0 1 0" range="-0.349 0.349" user="1103" />
                            <body name="robot0:ffproximal" pos="0 0 0">
                                <inertial pos="0 0 0.023" quat="0.707095 -0.00400054 0.00400054 0.707095" mass="0.014" diaginertia="1e-05 1e-05 1e-05" />
                                <joint name="robot0:FFJ2" pos="0 0 0" axis="1 0 0" range="0 1.571" user="1102" />
                                <geom name="robot0:C_ffproximal" class="robot0:DC_Hand" size="0.01 0.0175" pos="0 0 0.0175" type="capsule" />
                                <body name="robot0:ffmiddle" pos="0 0 0.035">
                                    <inertial pos="0 0 0.011" quat="0.707107 0 0 0.707107" mass="0.012" diaginertia="1e-05 1e-05 1e-05" />
                                    <joint name="robot0:FFJ1" pos="0 0 0" axis="1 0 0" range="0 1.571" user="1101" />
                                    <geom name="robot0:C_ffmiddle" class="robot0:DC_Hand" size="0.00805 0.0125" pos="0 0 0.0125" type="capsule" />
                                    <body name="robot0:ffdistal" pos="0 0 0.025">
                                        <inertial pos="0 0 0.015" quat="0.7071 -0.00300043 0.00300043 0.7071" mass="0.01" diaginertia="1e-05 1e-05 1e-05" />
                                        <joint name="robot0:FFJ0" pos="0 0 0" axis="1 0 0" range="0 1.571" user="1100" />
                                        <geom name="robot0:C_ffdistal" class="robot0:DC_Hand" size="0.00705 0.012" pos="0 0 0.012" type="capsule" condim="4" />
                                        <site name="robot0:S_fftip" pos="0 0 0.026" group="3" />
                                        <site name="robot0:Tch_fftip" class="robot0:D_Touch" pos="0 -0.004 0.018" />
                                    </body>
                                </body>
                            </body>
                        </body>
                        <body name="robot0:mfknuckle" pos="0.011 0 0.099">
                            <inertial pos="0 0 0" quat="0.520062 0.854102 0.00600072 -0.00300036" mass="0.008" diaginertia="1e-05 1e-05 1e-05" />
                            <joint name="robot0:MFJ3" pos="0 0 0" axis="0 1 0" range="-0.349 0.349" user="1107" />
                            <body name="robot0:mfproximal" pos="0 0 0">
                                <inertial pos="0 0 0.023" quat="0.707095 -0.00400054 0.00400054 0.707095" mass="0.014" diaginertia="1e-05 1e-05 1e-05" />
                                <joint name="robot0:MFJ2" pos="0 0 0" axis="1 0 0" range="0 1.571" user="1106" />
                                <geom name="robot0:C_mfproximal" class="robot0:DC_Hand" size="0.01 0.0175" pos="0 0 0.0135" type="capsule" />
                                <body name="robot0:mfmiddle" pos="0 0 0.035">
                                    <inertial pos="0 0 0.012" quat="0.707107 0 0 0.707107" mass="0.012" diaginertia="1e-05 1e-05 1e-05" />
                                    <joint name="robot0:MFJ1" pos="0 0 0" axis="1 0 0" range="0 1.571" user="1105" />
                                    <geom name="robot0:C_mfmiddle" class="robot0:DC_Hand" size="0.00805 0.0125" pos="0 0 0.0125" type="capsule" />
                                    <body name="robot0:mfdistal" pos="0 0 0.025">
                                        <inertial pos="0 0 0.015" quat="0.7071 -0.00300043 0.00300043 0.7071" mass="0.01" diaginertia="1e-05 1e-05 1e-05" />
                                        <joint name="robot0:MFJ0" pos="0 0 0" axis="1 0 0" range="0 1.571" user="1104" />
                                        <geom name="robot0:C_mfdistal" class="robot0:DC_Hand" size="0.00705 0.012" pos="0 0 0.012" type="capsule" condim="4" />
                                        <site name="robot0:S_mftip" pos="0 0 0.026" group="3" />
                                        <site name="robot0:Tch_mftip" class="robot0:D_Touch" pos="0 -0.004 0.018" />
                                    </body>
                                </body>
                            </body>
                        </body>
                        <body name="robot0:rfknuckle" pos="-0.012 -0.004 0.090">
                            <inertial pos="0 0 0" quat="0.520062 0.854102 0.00600072 -0.00300036" mass="0.008" diaginertia="1e-05 1e-05 1e-05" />
                            <joint name="robot0:RFJ3" pos="0 0 0" axis="0 1 0" range="-0.349 0.349" user="1111" />
                            <body name="robot0:rfproximal" pos="0 0 0">
                                <inertial pos="0 0 0.023" quat="0.707095 -0.00400054 0.00400054 0.707095" mass="0.014" diaginertia="1e-05 1e-05 1e-05" />
                                <joint name="robot0:RFJ2" pos="0 0 0" axis="1 0 0" range="0 1.571" user="1110" />
                                <geom name="robot0:C_rfproximal" class="robot0:DC_Hand" size="0.01 0.0175" pos="0 0 0.0175" type="capsule" />
                                <body name="robot0:rfmiddle" pos="0 0 0.033">
                                    <inertial pos="0 0 0.012" quat="0.707107 0 0 0.707107" mass="0.012" diaginertia="1e-05 1e-05 1e-05" />
                                    <joint name="robot0:RFJ1" pos="0 0 0" axis="1 0 0" range="0 1.571" user="1109" />
                                    <geom name="robot0:C_rfmiddle" class="robot0:DC_Hand" size="0.00805 0.0125" pos="0 0 0.0125" type="capsule" />
                                    <body name="robot0:rfdistal" pos="0 0 0.025">
                                        <inertial pos="0 0 0.015" quat="0.7071 -0.00300043 0.00300043 0.7071" mass="0.01" diaginertia="1e-05 1e-05 1e-05" />
                                        <joint name="robot0:RFJ0" pos="0 0 0" axis="1 0 0" range="0 1.571" user="1108" />
                                        <geom name="robot0:C_rfdistal" class="robot0:DC_Hand" size="0.00705 0.012" pos="0 0 0.012" type="capsule" condim="4" />
                                        <site name="robot0:S_rftip" pos="0 0 0.026" group="3" />
                                        <site name="robot0:Tch_rftip" class="robot0:D_Touch" pos="0 -0.004 0.018" />
                                    </body>
                                </body>
                            </body>
                        </body>
                        <body name="robot0:lfmetacarpal" pos="-0.017 0 0.044">
                            <inertial pos="-0.014 0.001 0.014" quat="0.709167 -0.0920216 -0.0630148 0.696164" mass="0.075" diaginertia="1e-05 1e-05 1e-05" />
                            <joint name="robot0:LFJ4" pos="0 0 0" axis="0.570977 0 0.820966" range="0 0.785" user="1116" />
                            <geom name="robot0:C_lfmetacarpal" class="robot0:DC_Hand" size="0.0095 0.0111 0.025" pos="-0.0165 0 0.01" type="box" rgba="0.4 0.5 0.6 0.2" />
                            <body name="robot0:lfknuckle" pos="-0.017 -0.008 0.035">
                                <inertial pos="0 0 0" quat="0.520062 0.854102 0.00600072 -0.00300036" mass="0.008" diaginertia="1e-05 1e-05 1e-05" />
                                <joint name="robot0:LFJ3" pos="0 0 0" axis="0 1 0" range="-0.45 0.349" user="1115" />
                                <body name="robot0:lfproximal" pos="0 0 0">
                                    <inertial pos="0 0 0.023" quat="0.707095 -0.00400054 0.00400054 0.707095" mass="0.014" diaginertia="1e-05 1e-05 1e-05" />
                                    <joint name="robot0:LFJ2" pos="0 0 0" axis="1 0 0" range="0 1.571" user="1114" />
                                    <geom name="robot0:C_lfproximal" class="robot0:DC_Hand" size="0.01 0.0138" pos="0 0 0.0175" type="capsule" />
                                    <body name="robot0:lfmiddle" pos="0 0 0.025">
                                        <inertial pos="0 0 0.012" quat="0.707107 0 0 0.707107" mass="0.012" diaginertia="1e-05 1e-05 1e-05" />
                                        <joint name="robot0:LFJ1" pos="0 0 0" axis="1 0 0" range="0 1.571" user="1113" />
                                        <geom name="robot0:C_lfmiddle" class="robot0:DC_Hand" size="0.00805 0.0125" pos="0 0 0.0125" type="capsule" />
                                        <body name="robot0:lfdistal" pos="0 0 0.020">
                                            <inertial pos="0 0 0.015" quat="0.7071 -0.00300043 0.00300043 0.7071" mass="0.01" diaginertia="1e-05 1e-05 1e-05" />
                                            <joint name="robot0:LFJ0" pos="0 0 0" axis="1 0 0" range="0 1.571" user="1112" />
                                            <geom name="robot0:C_lfdistal" class="robot0:DC_Hand" size="0.00705 0.012" pos="0 0 0.012" type="capsule" condim="4" />
                                            <site name="robot0:S_lftip" pos="0 0 0.026" group="3" />
                                            <site name="robot0:Tch_lftip" class="robot0:D_Touch" pos="0 -0.004 0.018" />
                                        </body>
                                    </body>
                                </body>
                            </body>
                        </body>
                        <body name="robot0:thbase" pos="0.031 -0.017 0.023" quat="0.923956 0 0.382499 0">
                            <inertial pos="0 0 0" mass="0.01" diaginertia="1e-05 1e-05 1e-05" />
                            <joint name="robot0:THJ4" pos="0 0 0" axis="0 0 -1" range="-1.047 1.047" user="1121" />
                            <geom name="robot0:V_thbase" size="0.001 0.001 0.001" type="box" group="1" />
                            <body name="robot0:thproximal" pos="0 0 0">
                                <inertial pos="0 0 0.017" quat="0.981604 0 0.000999597 0.190923" mass="0.016" diaginertia="1e-05 1e-05 1e-05" />
                                <joint name="robot0:THJ3" pos="0 0 0" axis="1 0 0" range="0 1.222" user="1120" />
                                <geom name="robot0:C_thproximal" class="robot0:DC_Hand" size="0.013 0.019" pos="0 0 0.019" type="capsule" rgba="0.4 0.5 0.6 0.1" />
                                <body name="robot0:thhub" pos="0 0 0.032">
                                    <inertial pos="0 0 0" mass="0.002" diaginertia="1e-05 1e-05 1e-05" />
                                    <joint name="robot0:THJ2" pos="0 0 0" axis="1 0 0" range="-0.209 0.209" user="1119" />
                                    <geom name="robot0:V_thhub" size="0.001 0.001 0.001" type="box" group="1" />
                                    <body name="robot0:thmiddle" pos="0 0 0">
                                        <inertial pos="0 0 0.016" quat="0.999971 -0.000999971 -0.00699979 0.00299991" mass="0.016" diaginertia="1e-05 1e-05 1e-05" />
                                        <joint name="robot0:THJ1" pos="0 0 0" axis="0 1 0" range="-0.524 0.524" user="1118" />
                                        <geom name="robot0:C_thmiddle" class="robot0:DC_Hand" size="0.011 0.016" pos="0 0 0.016" type="capsule" />
                                        <body name="robot0:thdistal" pos="0 -0.004 0.028">
                                            <inertial pos="0 0 0.016" quat="0.99887 -0.00499935 -0.0469939 0.00499935" mass="0.016" diaginertia="1e-05 1e-05 1e-05" />
                                            <joint name="robot0:THJ0" pos="0 0 0" axis="0 1 0" range="-1.571 0" user="1117" />
                                            <geom name="robot0:C_thdistal" class="robot0:DC_Hand" size="0.00918 0.013" pos="0 0.004 0.013" type="capsule" condim="4" />
                                            <site name="robot0:S_thtip" pos="0 0.004 0.0275" group="3" />
                                            <site name="robot0:Tch_thtip" class="robot0:D_Touch" pos="-0.005 0 0.02" size="0.005 0.011 0.016" />
                                        </body>
                                    </body>
                                </body>
                            </body>
                        </body>
                    </body>
                  </body>


                  </body>
                </body>
              </body>
            </body>
          </body>
        </body>
      </body>
    </body>
  </worldbody>
  <actuator>
    <motor name="L_Hip_x" joint="L_Hip_x" gear="125"/>
    <motor name="L_Hip_y" joint="L_Hip_y" gear="125"/>
    <motor name="L_Hip_z" joint="L_Hip_z" gear="125"/>
    <motor name="L_Knee_y" joint="L_Knee_y" gear="100"/>
    <motor name="L_Ankle_x" joint="L_Ankle_x" gear="50"/>
    <motor name="L_Ankle_y" joint="L_Ankle_y" gear="50"/>
    <motor name="L_Ankle_z" joint="L_Ankle_z" gear="50"/>
    <motor name="L_Toe_y" joint="L_Toe_y" gear="50"/>
    <motor name="R_Hip_x" joint="R_Hip_x" gear="125"/>
    <motor name="R_Hip_y" joint="R_Hip_y" gear="125"/>
    <motor name="R_Hip_z" joint="R_Hip_z" gear="125"/>
    <motor name="R_Knee_y" joint="R_Knee_y" gear="100"/>
    <motor name="R_Ankle_x" joint="R_Ankle_x" gear="50"/>
    <motor name="R_Ankle_y" joint="R_Ankle_y" gear="50"/>
    <motor name="R_Ankle_z" joint="R_Ankle_z" gear="50"/>
    <motor name="R_Toe_y" joint="R_Toe_y" gear="50"/>
    <motor name="Spine_x" joint="Spine_x" gear="125"/>
    <motor name="Spine_y" joint="Spine_y" gear="125"/>
    <motor name="Spine_z" joint="Spine_z" gear="125"/>
    <motor name="Neck_x" joint="Neck_x" gear="20"/>
    <motor name="Neck_y" joint="Neck_y" gear="20"/>
    <motor name="Neck_z" joint="Neck_z" gear="20"/>
    <motor name="L_Thorax_x" joint="L_Thorax_x" gear="50"/>
    <motor name="L_Shoulder_x" joint="L_Shoulder_x" gear="70"/>
    <motor name="L_Shoulder_y" joint="L_Shoulder_y" gear="70"/>
    <motor name="L_Shoulder_z" joint="L_Shoulder_z" gear="70"/>
    <motor name="L_Elbow_x" joint="L_Elbow_x" gear="60"/>
    <motor name="R_Thorax_x" joint="R_Thorax_x" gear="50"/>
    <motor name="R_Shoulder_x" joint="R_Shoulder_x" gear="70"/>
    <motor name="R_Shoulder_y" joint="R_Shoulder_y" gear="70"/>
    <motor name="R_Shoulder_z" joint="R_Shoulder_z" gear="70"/>
    <motor name="R_Elbow_x" joint="R_Elbow_x" gear="60"/>


   <position name="robot0:A_WRJ1" class="robot0:asset_class" user="2038" joint="robot0:WRJ1" ctrlrange="-0.489 0.14" kp="5" forcerange="-4.785 4.785"></position>
    <position name="robot0:A_WRJ0" class="robot0:asset_class" user="2036" joint="robot0:WRJ0" ctrlrange="-0.698 0.489" kp="5" forcerange="-2.175 2.175"></position>

    <position name="robot0:A_FFJ3" class="robot0:asset_class" user="2004" joint="robot0:FFJ3" ctrlrange="-0.349 0.349" kp="1" forcerange="-0.9 0.9"></position>
    <position name="robot0:A_FFJ2" class="robot0:asset_class" user="2002" joint="robot0:FFJ2" ctrlrange="0 1.571" kp="1" forcerange="-0.9 0.9"></position>
    <position name="robot0:A_FFJ1" class="robot0:asset_class" user="2000" joint="robot0:FFJ1" ctrlrange="0 1.571" kp="1" forcerange="-0.7245 0.7245"></position>
    <position name="robot0:A_MFJ3" class="robot0:asset_class" user="2010" joint="robot0:MFJ3" ctrlrange="-0.349 0.349" kp="1" forcerange="-0.9 0.9"></position>
    <position name="robot0:A_MFJ2" class="robot0:asset_class" user="2008" joint="robot0:MFJ2" ctrlrange="0 1.571" kp="1" forcerange="-0.9 0.9"></position>
    <position name="robot0:A_MFJ1" class="robot0:asset_class" user="2006" joint="robot0:MFJ1" ctrlrange="0 1.571" kp="1" forcerange="-0.7245 0.7245"></position>
    <position name="robot0:A_RFJ3" class="robot0:asset_class" user="2016" joint="robot0:RFJ3" ctrlrange="-0.349 0.349" kp="1" forcerange="-0.9 0.9"></position>
    <position name="robot0:A_RFJ2" class="robot0:asset_class" user="2014" joint="robot0:RFJ2" ctrlrange="0 1.571" kp="1" forcerange="-0.9 0.9"></position>
    <position name="robot0:A_RFJ1" class="robot0:asset_class" user="2012" joint="robot0:RFJ1" ctrlrange="0 1.571" kp="1" forcerange="-0.7245 0.7245"></position>
    <position name="robot0:A_LFJ4" class="robot0:asset_class" user="2024" joint="robot0:LFJ4" ctrlrange="0 0.785" kp="1" forcerange="-0.9 0.9"></position>
    <position name="robot0:A_LFJ3" class="robot0:asset_class" user="2022" joint="robot0:LFJ3" ctrlrange="-0.349 0.349" kp="1" forcerange="-0.9 0.9"></position>
    <position name="robot0:A_LFJ2" class="robot0:asset_class" user="2020" joint="robot0:LFJ2" ctrlrange="0 1.571" kp="1" forcerange="-0.9 0.9"></position>
    <position name="robot0:A_LFJ1" class="robot0:asset_class" user="2018" joint="robot0:LFJ1" ctrlrange="0 1.571" kp="1" forcerange="-0.7245 0.7245"></position>
    <position name="robot0:A_THJ4" class="robot0:asset_class" user="2034" joint="robot0:THJ4" ctrlrange="-1.047 1.047" kp="1" forcerange="-2.3722 2.3722"></position>
    <position name="robot0:A_THJ3" class="robot0:asset_class" user="2032" joint="robot0:THJ3" ctrlrange="0 1.222" kp="1" forcerange="-1.45 1.45"></position>
    <position name="robot0:A_THJ2" class="robot0:asset_class" user="2030" joint="robot0:THJ2" ctrlrange="-0.209 0.209" kp="1" forcerange="-0.99 0.99"></position>
    <position name="robot0:A_THJ1" class="robot0:asset_class" user="2028" joint="robot0:THJ1" ctrlrange="-0.524 0.524" kp="1" forcerange="-0.99 0.99"></position>
    <position name="robot0:A_THJ0" class="robot0:asset_class" user="2026" joint="robot0:THJ0" ctrlrange="-1.571 0" kp="1" forcerange="-0.81 0.81"></position>

  </actuator>

</mujoco>
